Workbook

Sheet Overview
A1: Balanced Questionnaire Control Panel
A2: Formula-driven composition and quality gates for 500 valid, scoreable, override-free questions.
A4: Selected questions | D4: Mandatory named-case | G4: Selected overrides | J4: Scoreable questions
A5: =COUNT('Selection Ledger'!$A$4:$A$503) -> 500 | D5: =COUNTIF('Selection Ledger'!$L$4:$L$503,"Yes") -> 186 | G5: =COUNTIF('Selection Ledger'!$N$4:$N$503,"*override:*") -> 0 | J5: =COUNTIF('Selection Ledger'!$AB$4:$AB$503,"Yes") -> 500
A8: The three official annulments were excluded and replaced by deterministic valid questions from Aragón 2020, Castilla-La Mancha 2022, and Castilla y León 2022. Four image-linked Andalucía questions were then replaced within the same exam/type quota cells with self-contained alternatives. All 500 selected questions are scoreable and require no separate image.
A10: Region | B10: Final target | C10: Actual | D10: Mandatory | E10: Supplemental | F10: Variance | H10: Primary type | I10: Actual | J10: Share
A11: Andalucía | B11: 34 | C11: =COUNTIF('Selection Ledger'!$D$4:$D$503,A11) -> 34 | D11: =COUNTIFS('Selection Ledger'!$D$4:$D$503,A11,'Selection Ledger'!$L$4:$L$503,"Yes") -> 0 | E11: =C11-D11 -> 34 | F11: =C11-B11 -> 0 | H11: Named clinical-case section | I11: =COUNTIF('Selection Ledger'!$I$4:$I$503,H11) -> 186 | J11: =I11/$A$5 -> 0.372
A12: Aragón | B12: 34 | C12: =COUNTIF('Selection Ledger'!$D$4:$D$503,A12) -> 34 | D12: =COUNTIFS('Selection Ledger'!$D$4:$D$503,A12,'Selection Ledger'!$L$4:$L$503,"Yes") -> 0 | E12: =C12-D12 -> 34 | F12: =C12-B12 -> 0 | H12: Standard/main | I12: =COUNTIF('Selection Ledger'!$I$4:$I$503,H12) -> 164 | J12: =I12/$A$5 -> 0.328
A13: Castilla y León | B13: 34 | C13: =COUNTIF('Selection Ledger'!$D$4:$D$503,A13) -> 34 | D13: =COUNTIFS('Selection Ledger'!$D$4:$D$503,A13,'Selection Ledger'!$L$4:$L$503,"Yes") -> 0 | E13: =C13-D13 -> 34 | F13: =C13-B13 -> 0 | H13: Other structured types | I13: =COUNTIF('Selection Ledger'!$I$4:$I$503,H13) -> 150 | J13: =I13/$A$5 -> 0.3
A14: Castilla-La Mancha | B14: 34 | C14: =COUNTIF('Selection Ledger'!$D$4:$D$503,A14) -> 34 | D14: =COUNTIFS('Selection Ledger'!$D$4:$D$503,A14,'Selection Ledger'!$L$4:$L$503,"Yes") -> 0 | E14: =C14-D14 -> 34 | F14: =C14-B14 -> 0
A15: Comunidad de Madrid | B15: 33 | C15: =COUNTIF('Selection Ledger'!$D$4:$D$503,A15) -> 33 | D15: =COUNTIFS('Selection Ledger'!$D$4:$D$503,A15,'Selection Ledger'!$L$4:$L$503,"Yes") -> 0 | E15: =C15-D15 -> 33 | F15: =C15-B15 -> 0
A16: Comunitat Valenciana | B16: 33 | C16: =COUNTIF('Selection Ledger'!$D$4:$D$503,A16) -> 33 | D16: =COUNTIFS('Selection Ledger'!$D$4:$D$503,A16,'Selection Ledger'!$L$4:$L$503,"Yes") -> 0 | E16: =C16-D16 -> 33 | F16: =C16-B16 -> 0 | H16: Formal question type | I16: Actual | J16: Share
A17: Galicia | B17: 33 | C17: =COUNTIF('Selection Ledger'!$D$4:$D$503,A17) -> 33 | D17: =COUNTIFS('Selection Ledger'!$D$4:$D$503,A17,'Selection Ledger'!$L$4:$L$503,"Yes") -> 0 | E17: =C17-D17 -> 33 | F17: =C17-B17 -> 0 | H17: Named clinical-case section | I17: =COUNTIF('Selection Ledger'!$J$4:$J$503,H17) -> 186 | J17: =I17/$A$5 -> 0.372
A18: Illes Balears | B18: 165 | C18: =COUNTIF('Selection Ledger'!$D$4:$D$503,A18) -> 165 | D18: =COUNTIFS('Selection Ledger'!$D$4:$D$503,A18,'Selection Ledger'!$L$4:$L$503,"Yes") -> 165 | E18: =C18-D18 -> 0 | F18: =C18-B18 -> 0 | H18: Standard/main | I18: =COUNTIF('Selection Ledger'!$J$4:$J$503,H18) -> 164 | J18: =I18/$A$5 -> 0.328
A19: La Rioja | B19: 33 | C19: =COUNTIF('Selection Ledger'!$D$4:$D$503,A19) -> 33 | D19: =COUNTIFS('Selection Ledger'!$D$4:$D$503,A19,'Selection Ledger'!$L$4:$L$503,"Yes") -> 0 | E19: =C19-D19 -> 33 | F19: =C19-B19 -> 0 | H19: Non-case reserve | I19: =COUNTIF('Selection Ledger'!$J$4:$J$503,H19) -> 103 | J19: =I19/$A$5 -> 0.206
A20: Navarra | B20: 34 | C20: =COUNTIF('Selection Ledger'!$D$4:$D$503,A20) -> 34 | D20: =COUNTIFS('Selection Ledger'!$D$4:$D$503,A20,'Selection Ledger'!$L$4:$L$503,"Yes") -> 21 | E20: =C20-D20 -> 13 | F20: =C20-B20 -> 0 | H20: Theoretical | I20: =COUNTIF('Selection Ledger'!$J$4:$J$503,H20) -> 17 | J20: =I20/$A$5 -> 0.034
A21: Región de Murcia | B21: 33 | C21: =COUNTIF('Selection Ledger'!$D$4:$D$503,A21) -> 33 | D21: =COUNTIFS('Selection Ledger'!$D$4:$D$503,A21,'Selection Ledger'!$L$4:$L$503,"Yes") -> 0 | E21: =C21-D21 -> 33 | F21: =C21-B21 -> 0 | H21: Practical | I21: =COUNTIF('Selection Ledger'!$J$4:$J$503,H21) -> 17 | J21: =I21/$A$5 -> 0.034
H22: Mixed theory–practical | I22: =COUNTIF('Selection Ledger'!$J$4:$J$503,H22) -> 13 | J22: =I22/$A$5 -> 0.026
A25: Quality gate | B25: Observed | C25: Expected | D25: Status
A26: Selected total | B26: =A5 -> 500 | C26: 500 | D26: =IF(B26=C26,"PASS","FAIL") -> PASS
A27: Override-tagged selected | B27: =COUNTIF('Selection Ledger'!$N$4:$N$503,"*override:*") -> 0 | C27: 0 | D27: =IF(B27=C27,"PASS","FAIL") -> PASS
A28: Declared nullified selected | B28: =COUNTIF('Selection Ledger'!$N$4:$N$503,"*nullified*") -> 0 | C28: 0 | D28: =IF(B28=C28,"PASS","FAIL") -> PASS
A29: Blank answer-key cells | B29: =COUNTBLANK('Answer Key'!$B$5:$B$504) -> 0 | C29: 0 | D29: =IF(B29=C29,"PASS","FAIL") -> PASS
A30: Duplicate source keys | B30: =SUMPRODUCT(--(COUNTIF('Selection Ledger'!$C$4:$C$503,'Selection Ledger'!$C$4:$C$503)>1)) -> 0 | C30: 0 | D30: =IF(B30=C30,"PASS","FAIL") -> PASS
A31: Answer-letter mismatches | B31: =SUMPRODUCT(--(UPPER('Answer Key'!$B$5:$B$504)<>UPPER('Selection Ledger'!$P$4:$P$503))) -> 0 | C31: 0 | D31: =IF(B31=C31,"PASS","FAIL") -> PASS
A32: Named-case rows missing context | B32: =COUNTIFS('Selection Ledger'!$I$4:$I$503,"Named clinical-case section",'Selection Ledger'!$R$4:$R$503,"") -> 0 | C32: 0 | D32: =IF(B32=C32,"PASS","FAIL") -> PASS

Sheet Questionnaire
A1: Balanced Digestive-System Questionnaire — 500 Questions
A2: Print-readable question blocks. Answers are separated; every required context is inline and no selected item needs a separate image.
A3: ITEM 1 · Illes Balears 2022 · illes-balears/2022 / Q1 · Named clinical-case section
A4: CLINICAL CONTEXT [BASE CLINICAL CONTEXT: illes-balears-2022-base-caso-1] Paciente de 57 años, sin antecedentes personales ni familiares de cáncer de colon ni de cáncer en otras localizaciones, fumador de 22 cigarrillos al día, con hábitos de vida sedentarios, enolismo de 60 gr/día, obesidad con un índice de masa corporal de 37 y una dieta rica en carnes rojas y procesadas.
A5: Señale la respuesta correcta en relación con el cáncer de colon:
A6: A. Es el tipo de cáncer con más incidencia en España. | E6: B. Su incidencia está aumentando en los últimos años.
A7: C. En la población de menos de 50 años su incidencia está bajando claramente. | E7: D. Las respuestas a) y b) son correctas.
A8: Context IDs: illes-balears-2022-base-caso-1 | Source exam PDF page: 3
A10: ITEM 2 · Illes Balears 2022 · illes-balears/2022 / Q2 · Named clinical-case section
A11: CLINICAL CONTEXT CONTINUES THE ACTIVE CONTEXT: illes-balears-2022-base-caso-1
A12: Señale la respuesta falsa en relación con los factores de riesgo del cáncer colorrectal:
A13: A. El consumo de tabaco incrementa el riesgo de cáncer de colon. | E13: B. El consumo de alcohol incrementa el riesgo de cáncer de colon.
A14: C. La obesidad no ha mostrado ser un factor de riesgo para el desarrollo del cáncer de colon. | E14: D. El ejercicio físico regular es un factor que reduce el riesgo de cáncer de colon.
A15: Context IDs: illes-balears-2022-base-caso-1 | Source exam PDF page: 3
A17: ITEM 3 · Illes Balears 2022 · illes-balears/2022 / Q3 · Named clinical-case section
A18: CLINICAL CONTEXT CONTINUES THE ACTIVE CONTEXT: illes-balears-2022-base-caso-1
A19: Señale la respuesta correcta en relación con la edad y el cáncer de colon:
A20: A. El cáncer de colon incrementa claramente su incidencia a partir de los 50. | E20: B. El cáncer de colon presenta la misma incidencia en cualquier edad.
A21: C. La edad no es un factor de riesgo determinante en el desarrollo del cáncer de colon. | E21: D. La edad es el único factor de riesgo determinante para el desarrollo de un cáncer colorrectal y no existen otros factores moduladores significativos.
A22: Context IDs: illes-balears-2022-base-caso-1 | Source exam PDF page: 3
A24: ITEM 4 · Illes Balears 2022 · illes-balears/2022 / Q4 · Named clinical-case section
A25: CLINICAL CONTEXT CONTINUES THE ACTIVE CONTEXT: illes-balears-2022-base-caso-1
A26: Señale la respuesta correcta en relación con el cáncer colorrectal (CCR):
A27: A. La dieta rica en carnes rojas y procesadas disminuye el riesgo de CCR. | E27: B. La dieta rica en frutas y vegetales disminuye el riesgo de CCR.
A28: C. La dieta rica en grasas y la obesidad disminuyen el riesgo de CCR. | E28: D. No se debe recomendar retirar el consumo de tabaco y de alcohol para prevenir el CCR.
A29: Context IDs: illes-balears-2022-base-caso-1 | Source exam PDF page: 4
A31: ITEM 5 · Illes Balears 2022 · illes-balears/2022 / Q5 · Named clinical-case section
A32: CLINICAL CONTEXT CONTINUES THE ACTIVE CONTEXT: illes-balears-2022-base-caso-1
A33: El paciente descrito inicialmente no presenta ningún tipo de sintomatología. Señale la respuesta correcta en relación con el programa de cribado del cáncer de colon:
A34: A. No tiene criterios para participar ya que solo se incluyen los pacientes de entre 60 y 75 años. | E34: B. Cumple criterios para ser incluido en el programa de cribado del CCR.
A35: C. La ausencia de antecedentes familiares es un criterio de exclusión del programa de cribado del CCR. | E35: D. La ausencia de síntomas es un criterio de exclusión del programa de cribado del CCR.
A36: Context IDs: illes-balears-2022-base-caso-1 | Source exam PDF page: 4
A38: ITEM 6 · Illes Balears 2022 · illes-balears/2022 / Q6 · Named clinical-case section
A39: CLINICAL CONTEXT CONTINUES THE ACTIVE CONTEXT: illes-balears-2022-base-caso-1
A40: Una vez incluido en el programa de cribado se hace la determinación de sangre oculta en heces (SOH) inmunológica cuantitativa, que resulta positiva. Señale la respuesta correcta:
A41: A. No se debe ofrecer ningún tipo de prueba complementaria. | E41: B. Se debe ofrecer al paciente hacer una segunda determinación de SOH.
A42: C. Se debe ofrecer al paciente hacer una colonoscopia. | E42: D. Si no hay síntomas no es necesario hacer una colonoscopia.
A43: Context IDs: illes-balears-2022-base-caso-1 | Source exam PDF page: 4
A45: ITEM 7 · Illes Balears 2022 · illes-balears/2022 / Q7 · Named clinical-case section
A46: CLINICAL CONTEXT CONTINUES THE ACTIVE CONTEXT: illes-balears-2022-base-caso-1
...

Sheet Question Data
A1: Question Data — Electronic Trace View
A2: Filterable source-aligned data for all 500 items. Use the Questionnaire sheet for the complete, print-readable question blocks.
A4: Item | B4: Region | C4: Year | D4: Source exam | E4: Exam part | F4: Source Q | G4: Primary type | H4: Formal question type | I4: Clinical context | J4: Question | K4: Option A | L4: Option B | M4: Option C | N4: Option D | O4: Context IDs | P4: Visual ID | Q4: PDF page
A5: 1 | B5: Illes Balears | C5: 2022 | D5: illes-balears/2022 | E5: caso-1 | F5: 1 | G5: Named clinical-case section | H5: Named clinical-case section | I5: [BASE CLINICAL CONTEXT: illes-balears-2022-base-caso-1] Paciente de 57 años, sin antecedentes personales ni familiares de cáncer de colon ni de cáncer en otras localizaciones, fumador de 22 cigarrillos al día, con hábitos de vida sedentarios, enolismo de 60 gr/día, obesidad con un índice de masa corporal de 37 y una dieta rica en carnes rojas y procesadas. | J5: Señale la respuesta correcta en relación con el cáncer de colon: | K5: Es el tipo de cáncer con más incidencia en España. | L5: Su incidencia está aumentando en los últimos años. | M5: En la población de menos de 50 años su incidencia está bajando claramente. | N5: Las respuestas a) y b) son correctas. | O5: illes-balears-2022-base-caso-1 | Q5: 3
A6: 2 | B6: Illes Balears | C6: 2022 | D6: illes-balears/2022 | E6: caso-1 | F6: 2 | G6: Named clinical-case section | H6: Named clinical-case section | I6: CONTINUES THE ACTIVE CONTEXT: illes-balears-2022-base-caso-1 | J6: Señale la respuesta falsa en relación con los factores de riesgo del cáncer colorrectal: | K6: El consumo de tabaco incrementa el riesgo de cáncer de colon. | L6: El consumo de alcohol incrementa el riesgo de cáncer de colon. | M6: La obesidad no ha mostrado ser un factor de riesgo para el desarrollo del cáncer de colon. | N6: El ejercicio físico regular es un factor que reduce el riesgo de cáncer de colon. | O6: illes-balears-2022-base-caso-1 | Q6: 3
A7: 3 | B7: Illes Balears | C7: 2022 | D7: illes-balears/2022 | E7: caso-1 | F7: 3 | G7: Named clinical-case section | H7: Named clinical-case section | I7: CONTINUES THE ACTIVE CONTEXT: illes-balears-2022-base-caso-1 | J7: Señale la respuesta correcta en relación con la edad y el cáncer de colon: | K7: El cáncer de colon incrementa claramente su incidencia a partir de los 50. | L7: El cáncer de colon presenta la misma incidencia en cualquier edad. | M7: La edad no es un factor de riesgo determinante en el desarrollo del cáncer de colon. | N7: La edad es el único factor de riesgo determinante para el desarrollo de un cáncer colorrectal y no existen otros factores moduladores significativos. | O7: illes-balears-2022-base-caso-1 | Q7: 3
A8: 4 | B8: Illes Balears | C8: 2022 | D8: illes-balears/2022 | E8: caso-1 | F8: 4 | G8: Named clinical-case section | H8: Named clinical-case section | I8: CONTINUES THE ACTIVE CONTEXT: illes-balears-2022-base-caso-1 | J8: Señale la respuesta correcta en relación con el cáncer colorrectal (CCR): | K8: La dieta rica en carnes rojas y procesadas disminuye el riesgo de CCR. | L8: La dieta rica en frutas y vegetales disminuye el riesgo de CCR. | M8: La dieta rica en grasas y la obesidad disminuyen el riesgo de CCR. | N8: No se debe recomendar retirar el consumo de tabaco y de alcohol para prevenir el CCR. | O8: illes-balears-2022-base-caso-1 | Q8: 4
A9: 5 | B9: Illes Balears | C9: 2022 | D9: illes-balears/2022 | E9: caso-1 | F9: 5 | G9: Named clinical-case section | H9: Named clinical-case section | I9: CONTINUES THE ACTIVE CONTEXT: illes-balears-2022-base-caso-1 | J9: El paciente descrito inicialmente no presenta ningún tipo de sintomatología. Señale la respuesta correcta en relación con el programa de cribado del cáncer de colon: | K9: No tiene criterios para participar ya que solo se incluyen los pacientes de entre 60 y 75 años. | L9: Cumple criterios para ser incluido en el programa de cribado del CCR. | M9: La ausencia de antecedentes familiares es un criterio de exclusión del programa de cribado del CCR. | N9: La ausencia de síntomas es un criterio de exclusión del programa de cribado del CCR. | O9: illes-balears-2022-base-caso-1 | Q9: 4
A10: 6 | B10: Illes Balears | C10: 2022 | D10: illes-balears/2022 | E10: caso-1 | F10: 6 | G10: Named clinical-case section | H10: Named clinical-case section | I10: CONTINUES THE ACTIVE CONTEXT: illes-balears-2022-base-caso-1 | J10: Una vez incluido en el programa de cribado se hace la determinación de sangre oculta en heces (SOH) inmunológica cuantitativa, que resulta positiva. Señale la respuesta correcta: | K10: No se debe ofrecer ningún tipo de prueba complementaria. | L10: Se debe ofrecer al paciente hacer una segunda determinación de SOH. | M10: Se debe ofrecer al paciente hacer una colonoscopia. | N10: Si no hay síntomas no es necesario hacer una colonoscopia. | O10: illes-balears-2022-base-caso-1 | Q10: 4
A11: 7 | B11: Illes Balears | C11: 2022 | D11: illes-balears/2022 | E11: caso-1 | F11: 7 | G11: Named clinical-case section | H11: Named clinical-case section | I11: CONTINUES THE ACTIVE CONTEXT: illes-balears-2022-base-caso-1 | J11: Señale la respuesta falsa en relación con la calidad de las endoscopias del programa de cribado: | K11: Deben ser procedimientos hechos por endoscopistas de alta cualificación para poder detectar y tratar las lesiones. | L11: Se deben hacer en gabinetes con programación específica separada de las endoscopias de rutina. | M11: Se debe disponer de equipamientos de la máxima calidad para optimizar la detección de las lesiones. | N11: Las endoscopias del programa de cribado pueden hacerse en cualquier gabinete y por cualquier tipo de endoscopista independientemente de su tasa de detección de adenomas. | O11: illes-balears-2022-base-caso-1 | Q11: 5
A12: 8 | B12: Illes Balears | C12: 2022 | D12: illes-balears/2022 | E12: caso-1 | F12: 8 | G12: Named clinical-case section | H12: Named clinical-case section | I12: CONTINUES THE ACTIVE CONTEXT: illes-balears-2022-base-caso-1 | J12: La colonoscopia es normal hasta el ciego, pero en la estratificación del grado de limpieza, según la escala de Boston, el resultado ha sido el siguiente: Colon derecho: 1 Colon transverso: 1 Colon izquierdo: 1 Colon total: 3 puntos. Señale la respuesta correcta: | K12: Se debe repetir la colonoscopia para conseguir una puntuación total de 6 puntos (o superior) con un mínimo de dos puntos en cada tramo. | L12: Se debe repetir la colonoscopia para conseguir una puntuación total de 6 puntos (o superior), independientemente de la puntuación de cada tramo. | M12: No se debe repetir la colonoscopia, este grado de limpieza del colon es adecuado. | N12: El grado de limpieza del colon no es un factor determinante para la tasa de detección de adenomas ni para evitar la neoplasia de intervalo. | O12: illes-balears-2022-base-caso-1 | Q12: 5
A13: 9 | B13: Illes Balears | C13: 2022 | D13: illes-balears/2022 | E13: caso-1 | F13: 9 | G13: Named clinical-case section | H13: Named clinical-case section | I13: CONTINUES THE ACTIVE CONTEXT: illes-balears-2022-base-caso-1 | J13: Se repite la colonoscopia y se objetiva la presencia de un pólipo único pediculado de 15 mm a 30 cm del margen anal. La colonoscopia es completa hasta el ciego, con 9 puntos en la escala de Boston. Se hace una polipectomía con una resección completa del pólipo con su pedículo. En el estudio histológico se describe un adenoma tubulovelloso con displasia de alto grado focal estrictamente superficial, con márgenes de resección libres de tejido adenomatoso con margen de resección amplio en el pedículo. Señale la respuesta correcta: | K13: Se requiere un tratamiento quirúrgico complementario para asegurar la curación de la lesión. | L13: La lesión ha quedado curada tras la resección endoscópica. | M13: Se debe repetir la colonoscopia de inmediato para revisar la escara de la polipectomía dado el riesgo alto de lesión residual. | N13: Se debe hacer una TC abdominal complementaria como estudio de la extensión de la lesión. | O13: illes-balears-2022-base-caso-1 | Q13: 6
A14: 10 | B14: Illes Balears | C14: 2022 | D14: illes-balears/2022 | E14: caso-1 | F14: 10 | G14: Named clinical-case section | H14: Named clinical-case section | I14: CONTINUES THE ACTIVE CONTEXT: illes-balears-2022-base-caso-1 | J14: Señale la respuesta correcta según las últimas guías clínicas en cuanto al control endoscópico de la lesión descrita: | K14: Se requiere una revisión endoscópica en 6 meses. | L14: No requiere una revisión endoscópica ya que se trata de una lesión de riesgo bajo. | M14: Este paciente será susceptible de una colonoscopia anual a partir de ahora. | N14: Una revisión endoscópica dentro de tres años es suficiente. | O14: illes-balears-2022-base-caso-1 | Q14: 6
A15: 11 | B15: Illes Balears | C15: 2022 | D15: illes-balears/2022 | E15: caso-1 | F15: 11 | G15: Named clinical-case section | H15: Named clinical-case section | I15: CONTINUES THE ACTIVE CONTEXT: illes-balears-2022-base-caso-1 | J15: Este paciente tiene un hermano de 52 años, asintomático. En la familia no existen otros antecedentes de CCR. ¿Qué recomendación debemos dar al hermano en cuanto a prevención del CCR? | K15: Es susceptible de endoscopia de forma inmediata. | L15: No requiere ningún tipo de procedimiento dada la edad y la ausencia de clínica asociada. | M15: En este caso se recomienda el control por medio de una SOH bianual. | N15: Se le debe ofrecer una colonoscopia anual como herramienta de prevención más eficaz a nivel de coste. | O15: illes-balears-2022-base-caso-1 | Q15: 6
A16: 12 | B16: Illes Balears | C16: 2022 | D16: illes-balears/2022 | E16: caso-1 | F16: 12 | G16: Named clinical-case section | H16: Named clinical-case section | I16: CONTINUES THE ACTIVE CONTEXT: illes-balears-2022-base-caso-1 | J16: El paciente deja de acudir a les consultas externas. Regresa al cabo de siete años con un cuadro de rectorragias asociadas a una pérdida de ocho quilos. Señale la respuesta correcta: | K16: No requiere una colonoscopia porque tiene una de hace siete años. | L16: Requiere colonoscopia por la clínica que presenta para descartar un CCR. | M16: En este caso basta con un análisis de SOH. | N16: La exploración inicial debe ser una ecografía abdominal. | O16: illes-balears-2022-base-caso-1 | Q16: 7
... A190: 186 | B190: Navarra | C190: 2022 | D190: navarra/2022 | E190: reserva-casos-clinicos | F190: 111 | G190: Named clinical-case section | H190: Named clinical-case section | I190: [FULL CLINICAL CONTEXT: navarra-2022-case-03] Varón de 65 años con antecedente de cirrosis hepática por VHC genotipo 3 (nunca tratado), sin otras comorbilidades, que ingresa por hematemesis. Se realiza gastroscopia visualizándose varices esofágicas grandes, una de ellas con sangrado activo y dos de ellas con extensión a curvadura menor gástrica. El paciente no presenta ascitis ni fiebre y desde el punto de vista hemodinámico tiene TA 100/60 mmHg, FC 75lpm, SatO2 94% FiO2 21%. Analítica: Hemoglobina 8,5 g/dL, plaquetas 78 x 109/L, actividad de protrombina 52%. Creatinina 0,98 mg/dL, Sodio 129 mmol/L, bilirrubina total 3,1 mg/dL, albúmina 32 g/L. AST 125 U/L, ALT 101 U/L. Serologías: IgM e IgG VHA negativo, HBsAg negativo, anti-HBs positivo, HBcAc total positivo, VIH negativo. Ecografía abdominal: Hígado con contornos nodulares y aumento de la ecogenicidad hepática con aspecto granular, sugestivo de hepatopatía crónica. No se objetivan lesiones focales. Vena porta de calibre normal con flujo hepatópeto. Esplenomegalia homogénea de 17,5 cm. Circulación colateral en espacio esplenorrenal. No líquido libre intraabdominal | J190: Pregunta de reserva Caso Clínico número 3: A las 72 horas de la gastroscopia inicial el paciente presenta nuevo episodio de hematemesis atribuible a sangrado variceal. Analíticamente destaca hemoglobina de 7,5g/dL, plaquetas 50 x 109/L, INR 2, actividad de protrombina 33%, fibrinógeno 200mg/dL, creatinina 1 mg/dL, bilirrubina total 2,8 mg/dL, ¿cuál de las siguientes actuaciones sería INCORRECTA?: | K190: Segundo intento de hemostasia endoscópica | L190: Trasfusión de 1 gramo de fibrinógeno | M190: Sería candidato a un TIPS de rescate | N190: El resangrado variceal tras un tratamiento endoscópico inicial puede ocurrir en el 10 -20% de los pacientes | O190: navarra-2022-case-03 | Q190: 26
A191: 187 | B191: Comunidad de Madrid | C191: 2021 | D191: comunidad-de-madrid/2021 | E191: main | F191: 48 | G191: Standard/main | H191: Standard/main | J191: ¿A cuál de los siguientes pacientes, con un episodio de hemorragia digestiva baja (HDB), autolimitada, atendido en Urgencias, daría usted el alta y procedería a realizar su estudio y manejo de forma mbulatoria? | K191: Varón, 73 años, sin episodios previos de HDB, tacto rectal con dedil limpio, Fc 63 lpm, TAS 133mm Hg, Hb 16 g/dl. | L191: Mujer, 52 años, HDB hace 8 meses atendida en otro centro, tacto rectal con dedil limpio, Fc 93 lpm, TAS 112mm Hg, Hb 10,3 g/dl. | M191: Varón, 57 años, sin episodios previos de HDB, tacto rectal con restos hemáticos, Fc 85 lpm, TAS 120mm Hg, Hb 11,2 g/dl. | N191: Mujer, 72 años, sin episodios previos, tacto rectal con dedil limpio, 92 lpm, TAS 109 mm Hg, Hb 12,5 g/dl. | Q191: 10
A192: 188 | B192: Castilla y León | C192: 2019 | D192: castilla-y-leon/2019 | E192: reserva-especifica | F192: 160 | G192: Other structured types | H192: Non-case reserve | J192: En una hepatitis aguda, de los síntomas abajo indicados ¿Cuál de ellos aconsejaría el ingreso del/la paciente? | K192: Ascitis | L192: Datos de encefalopatía | M192: Síntomas de hipoglucemia | N192: Todos los anteriores | Q192: 36
A193: 189 | B193: Región de Murcia | C193: 2019 | D193: region-de-murcia/2019 | E193: main | F193: 140 | G193: Standard/main | H193: Standard/main | J193: En relación al tratamiento de la ascitis en el paciente cirrótico, señale la respuesta falsa: | K193: La paracentesis de gran volumen (PGV) se debe realizar conjuntamente con la administración de albumina iv a razón de 80 g por litro extraído. | L193: En PGV de más de 5 litros el uso de expansores plasmáticos distintos a la albúmina no está recomendado. | M193: Los pacientes con un primer episodio de ascitis grado 2 (moderada) deben recibir solo antagonistas de la aldosterona, empezando a dosis de 100 mg/día. | N193: La restricción moderada de la ingesta de sal es un componente importante en el manejo de la ascitis. | Q193: 23
A194: 190 | B194: Comunidad de Madrid | C194: 2021 | D194: comunidad-de-madrid/2021 | E194: main | F194: 112 | G194: Standard/main | H194: Standard/main | J194: Señala cual NO es un efecto secundario de tacrolimus | K194: Insuficiencia renal | L194: Cefalea | M194: Convulsiones | N194: Pancreatitis aguda | Q194: 21
A195: 191 | B195: Galicia | C195: 2016 | D195: galicia/ope-2016 | E195: reserva-especifica | F195: 110 | G195: Other structured types | H195: Non-case reserve | J195: Señale la respuesta correcta en relación con la hepatitis por VHC: | K195: Todo paciente con hepatitis aguda por VHC debe recibir tratamiento antiviral. | L195: El tratamiento con ledipasvir y sofosbuvir durante 4 ó 6 semanas es muy seguro y eficaz en pacientes con hepatitis aguda por VHC con genotipo 1. | M195: El tratamiento de la hepatitis C post trasplante hepático está indicado en todos los pacientes, estando contraindicada la ribavirina. | N195: En pacientes con cirrosis por VHC no existen exámenes no invasivos que permitan descartar con un 90 por ciento de seguridad la existencia de varices esofágicas. | Q195: 26
A196: 192 | B196: Navarra | C196: 2022 | D196: navarra/2022 | E196: teorico-practica | F196: 75 | G196: Other structured types | H196: Mixed theory–practical | J196: Varón de 58 años que acude a urgencias por dolor agudo y constante en hipocondrio derecho, con náuseas, vómitos y fiebre de 38º. A la exploración presente ictericia e hipersensibilidad a la palpación en hipocondrio derecho. Se solicita una ecografía abdominal observando colelitiasis múltiple y dilatación de vía intrahepática sin poder valorar colédoco ni región pancreática por interposición de gas. Se completa con un TC observando litiasis en conducto cístico de 15 mm, dilatación de conducto hepático común y vía biliar intrahepática, estando el colédoco distal normal. ¿Cuál de los siguientes es el diagnóstico MÁS probable? | K196: Colangiocarcinoma tipo Klatskin | L196: Quiste de colédoco | M196: Síndrome de Mirizzi | N196: Colangiocarcinoma proximal | Q196: 16
A197: 193 | B197: Andalucía | C197: 2021 | D197: andalucia/2021-22-libre | E197: cuestionario-practico | F197: 126 | G197: Other structured types | H197: Practical | I197: [Full clinical context: andalucia-2021-22-libre-case-007] Una mujer de 62 años acude para realización de colonoscopia por test de sangre oculta en heces positivo en el contexto del programa de cribado poblacional de cáncer colorrectal de Andalucía. Se encontraba asintomática y no tenía comorbilidades ni antecedentes personales ni familiares de cáncer colorrectal. Se realiza colonoscopia hasta ciego, bajo sedación profunda, con un tiempo de retirada de 18 minutos. Se encontró un pólipo 0-Ip de 14mm en sigma, que se extirpa de forma completa y en bloque, informado por el patólogo como adenoma tubulovelloso con displasia de bajo grado. No se encontraron otras lesiones. La puntuación de la escala de Boston fue 5 (2 en colon izquierdo, 1 en colon transverso y 1 en ciego-colon ascendente). | J197: Realizado árbol genealógico familiar, no hay historia familiar de cáncer y el estudio inmunohistoquímico muestra tinción positiva (expresión) de las cuatro proteínas MMR (MLH1, MSH2, MSH6, PMS2). ¿Cuál sería la actitud preventiva más adecuada a seguir con su hijo de 35 años, siguiendo las recomendaciones más recientes de las guías de práctica clínica europea y española? | K197: Iniciar ya colonoscopias, con una periodicidad cada 10 años. | L197: Participar en el programa de cribado poblacional de cáncer colorrectal de Andalucía cuando se le invite. | M197: Iniciar colonoscopias a partir de los 40 años con una periodicidad cada 5 años. | N197: Iniciar colonoscopias a partir de los 50 años con una periodicidad cada 5 años. | O197: andalucia-2021-22-libre-case-007 | Q197: 33
A198: 194 | B198: Comunitat Valenciana | C198: 2022 | D198: comunitat-valenciana/2022 | E198: main-47-80 | F198: 56 | G198: Standard/main | H198: Standard/main | J198: Paciente con hepatitis crónica B con ALT 35 UI, DNA-VHB 9800 UI y Fibroscan 9,5 Kpa debe tratarse con: | K198: Interferon pegilado indefinido. | L198: Glecaprevir. | M198: Tenofovir indefinido. | N198: No tiene indicación de tratamiento. | Q198: 18
A199: 195 | B199: Aragón | C199: 2020 | D199: aragon/2020 | E199: main | F199: 93 | G199: Standard/main | H199: Standard/main | J199: En la enfermedad perianal (enfermedad de Crohn) si hay dolor intenso, usted sospechará: | K199: Absceso. | L199: Fístula compleja. | M199: Fístula transesfinteriana. | N199: Actividad rectal. | Q199: 18
A200: 196 | B200: Comunidad de Madrid | C200: 2021 | D200: comunidad-de-madrid/2021 | E200: main | F200: 135 | G200: Standard/main | H200: Standard/main | J200: En el contexto de un paciente con colangitis biliar primaria ¿qué hallazgo histológico es característico y se considera diagnóstico cuando se observa en la biopsia hepática? | K200: Cuerpos de Councilman | L200: Infiltrado linfocítico periportal con destrucción de los ductos biliares | M200: Fibrosis en puentes | N200: Granulomas no caseificantes | Q200: 24
A201: 197 | B201: Galicia | C201: 2016 | D201: galicia/ope-2016 | E201: reserva-especifica | F201: 103 | G201: Other structured types | H201: Non-case reserve | J201: ¿En cuál de las siguientes entidades no está recomendado, según las guías EASL, realizar estudios para detectar hemocromatosis? | K201: Diabetes tipo I. | L201: Diabetes tipo II. | M201: Porfiria cutánea tardía. | N201: Condrocalcinosis. | Q201: 24
A202: 198 | B202: Castilla-La Mancha | C202: 2017 | D202: castilla-la-mancha/2017-2018 | E202: reserva-especifica | F202: 102 | G202: Other structured types | H202: Non-case reserve | J202: En los gráficos de cajas (box-plot, box and whisker plot), ¿Qué representa la línea horizontal que está dentro de la caja? | K202: La moda | L202: Cuartil 2 | M202: El rango | N202: Desviación estándar | Q202: 18
A203: 199 | B203: Andalucía | C203: 2021 | D203: andalucia/2021-22-libre | E203: cuestionario-practico | F203: 134 | G203: Other structured types | H203: Practical | I203: [Full clinical context: andalucia-2021-22-libre-case-010] Paciente varón de 72 años, exfumador, con antecedentes de diabetes mellitus tipo 2, hipertensión arterial, hiperuricemia, enfermedad renal crónica y enfermedad pulmonar obstructiva crónica. En los últimos años presenta, además, arteriopatía obliterante crónica grado IV con amputación de falanges distales, enfermedad coronaria con afectación de tres vasos, insuficiencia mitral severa y disfunción del ventrículo izquierdo que precisó de plastia mitral con anillo y doble bypass. Se encontraba en tratamiento con ácido acetilsalicílico, clopidogrel, bisoprolol, furosemida, simvastatina, nitroglicerina, alopurinol, furosemida, omeprazol, bromuro de tiotropio, salmeterol y fluticasona. Acude a urgencias por dolor intestinal de intensidad moderada y rectorragia de 24 horas de evolución. No presentaba urgencia defecatoria ni refería fiebre, náuseas o vómitos. Tampoco recibió nuevos fármacos en los días previos. A su llegada a urgencias presentó tendencia a la hipotensión (tensión arterial 80/50 mmHg) que remontó con sueroterapia. No se constataron signos de hipoperfusión periférica. La exploración abdominal era dolorosa durante la palpación de la fosa ilíaca izquierda, sin datos de irritación peritoneal. Analíticamente destacaba hemoglobina de 9.2 gr/dL, con elevación de reactantes de fase aguda (proteína C reactiva 84 mg/L, leucocitos 16.500/mcL) y de creatinquinasa 994 U/l, siendo el resto normal. | J203: En relación a las pruebas complementarias necesarias en función del diagnóstico inicial, ¿Cuál de estas afirmaciones es falsa?: | K203: Se deben obtener muestras de heces para cultivo, parásitos y toxina de Clostridium difficile. | L203: La tomografía computarizada (TC) es el examen de imagen más útil. | M203: La colonoscopia es la técnica principal para el diagnóstico, siempre que no haya datos de peritonitis. | N203: La leucocitosis en un hallazgo frecuente desde las fases iniciales de la enfermedad. | O203: andalucia-2021-22-libre-case-010 | Q203: 36
A204: 200 | B204: La Rioja | C204: 2021 | D204: la-rioja/2020-2021 | E204: reserva | F204: 109 | G204: Other structured types | H204: Non-case reserve | J204: El tratamiento indicado en la Enfermedad de Caroli limitada a un solo lóbulo es: | K204: Ácido Ursodesoxicólico. | L204: Trasplante Hepático. | M204: Resección quirúrgica del lóbulo afectado. | N204: Litotricia extracorpórea. | Q204: 39
A205: 201 | B205: Región de Murcia | C205: 2019 | D205: region-de-murcia/2019 | E205: main | F205: 16 | G205: Standard/main | H205: Standard/main | J205: En el tratamiento del cáncer de esófago, señale la opción FALSA: | K205: En pacientes con adenocarcinoma esofágico en estadio T1a N0 M0 la terapéutica endoscópica es de elección. | L205: La esofagectomía radical y transtorácica (procedimiento de Ivor-Lewis) es la técnica quirúrgica de elección en el cáncer de esófago localizado, más allá de las etapas muy tempranas (T1b-T2 N0 M0). | M205: En los pacientes con adenocarcinoma de esófago con enfermedad localmente avanzada (T3-T4 N1-3 M0), después de una respuesta tumoral completa a la quimio radioterapia, nunca es preciso realizar cirugía. | N205: En pacientes con enfermedad metastásica (M1) de adenocarcinoma esofágico y buen estado general, está indicada la quimioterapia como tratamiento paliativo. | Q205: 3
A206: 202 | B206: Comunitat Valenciana | C206: 2022 | D206: comunitat-valenciana/2022 | E206: main-47-80 | F206: 54 | G206: Standard/main | H206: Standard/main | J206: Sólo una de las siguientes frases referentes al Dolor Rectal Funcional no es cierta, señálela: | K206: Los episodios de dolor en la Proctalgia Fugax duran de segundos a minutos. | L206: El Síndrome del Elevador del Ano afecta típicamente a mujeres de menos 45 años. | M206: Los criterios de Roma IV reconocen tres tipos de Dolor Rectal Funcional: Proctalgia Fugax, el Síndrome del Elevador del Ano y la Fisura Anal Crónica Idiopática. | N206: El salbutamol inhalado se utiliza para el tratamiento del Síndrome del Elevador del Ano. | Q206: 17
A207: 203 | B207: Aragón | C207: 2017 | D207: aragon/2017 | E207: reserva-especifica | F207: 109 | G207: Other structured types | H207: Non-case reserve | J207: Entre los datos siguientes uno NO es típico del síndrome hepatorenal tipo I? | K207: Sodio en sangre 115. | L207: Creatinina en sangre 5 mg/dl. | M207: Excreción de sodio en orina 50%. | N207: Proteinuria indetectable. | Q207: 39
A208: 204 | B208: Comunitat Valenciana | C208: 2022 | D208: comunitat-valenciana/2022 | E208: main | F208: 23 | G208: Standard/main | H208: Standard/main | J208: Señale cuál de las siguientes respuestas hace referencia a una prueba cuantitativa de función hepática: | K208: Eliminación del verde de Indocianina. | L208: Prueba de espiración de aminopirina. | M208: Eliminación de cafeína. | N208: Todas son correctas. | Q208: 9
A209: 205 | B209: Comunitat Valenciana | C209: 2022 | D209: comunitat-valenciana/2022 | E209: main | F209: 6 | G209: Standard/main | H209: Standard/main | J209: De conformidad con el Capítulo IV del V Convenio Colectivo del Consorcio HGUV –Planificación, Ordenación y Gestión del empleo público- ¿cuál de las siguientes plazas quedan excluidas de su regulación? | K209: Las de libre designación. | L209: Las plazas asistenciales vinculadas a otras de carácter docente. | M209: Las plazas de jefatura. | N209: Todas las respuestas anteriores son correctas. | Q209: 4
A210: 206 | B210: Castilla-La Mancha | C210: 2017 | D210: castilla-la-mancha/2017-2018 | E210: main | F210: 53 | G210: Standard/main | H210: Standard/main | J210: Señale cuál de los siguientes fármacos NO se ha relacionado con pancreatitis aguda | K210: Azatioprina | L210: Ácido valproico | M210: Tamsulosina | N210: IECA | Q210: 10
A211: 207 | B211: Región de Murcia | C211: 2019 | D211: region-de-murcia/2019 | E211: main | F211: 99 | G211: Standard/main | H211: Standard/main | J211: Con respecto al tratamiento farmacológico de la pancreatitis crónica, señale la opción cierta: | K211: No existen datos que apoyen el uso de omeprazol asociado al tratamiento sustitutivo enzimático. | L211: En la diabetes mellitus secundaria a pancreatitis crónica está indicado el tratamiento inicial con antidiabéticos orales. | M211: El tratamiento sustitutivo enzimático se debe controlar siempre mediante test de funcionalismo pancreático. | N211: La dosis de tratamiento sustitutivo enzimático correcta es de 40000-50000 unidades con las comidas principales y 20000-25000 con los snacks. | Q211: 17
A212: 208 | B212: La Rioja | C212: 2021 | D212: la-rioja/2020-2021 | E212: reserva | F212: 103 | G212: Other structured types | H212: Non-case reserve | J212: Cuál de los siguientes no es un criterio de definición de donante marginal para trasplante hepático: | K212: Edad del donante mayor de 65 años. | L212: Un IMC mayor de 30. | M212: Esteatosis hepática mayor del 60%. | N212: Bilirrubina en suero mayor de 3 mg/dL. | Q212: 37
A213: 209 | B213: Castilla-La Mancha | C213: 2022 | D213: castilla-la-mancha/2022 | E213: main | F213: 17 | G213: Standard/main | H213: Standard/main | J213: Paciente con cáncer gástrico precoz bien diferenciado sin signos endoscópicos sugestivos de invasión submucosa en el que se plantea realizar una resección endoscópica. Señale la respuesta falsa | K213: Las técnicas de cromoendoscopia pueden ser útiles para determinar los límites de la lesión. | L213: La ecoendoscopia puede ser útil para evaluar la profundidad de la lesión. | M213: Se debería suprimir el tratamiento con inhibidores de la bomba de protones pues aumentan las complicaciones tras la resección. | N213: La resección endoscópica podría realizarse en lesiones menores o iguales a 2 centímetros no ulceradas. | Q213: 4
A214: 210 | B214: Comunitat Valenciana | C214: 2022 | D214: comunitat-valenciana/2022 | E214: main-47-80 | F214: 77 | G214: Standard/main | H214: Standard/main | J214: Según la European Society of Gastrointestinal Endoscopy (ESGE) señale cuál de las siguientes afirmaciones en el tratamiento de la estenosis biliar secundaria a pancreatitis crónica no es cierta: | K214: La elevación asintomática de la fosfatasa alcalina tres veces los limites altos de la normalidad con elevación de la bilirrubina durante 1 mes se acepta como indicación para el drenaje de la vía biliar | L214: Se debe considerar la cirugía cuando hay fracaso del tratamiento endoscópico después de 1 año. | M214: Se recomienda la utilización de prótesis metálicas autoexpandibles no cubiertas. | N214: La ictericia se puede resolver espontáneamente en el plazo de 1 mes en el 20-50% de los casos. | Q214: 22
...

Sheet Answer Key
A1: Answer Key
A2: Print area: item, controlling letter, and full answer text. Additional source fields remain available electronically to the right.
A4: Item | B4: Correct letter | C4: Correct option text | D4: Region | E4: Year | F4: Source exam | G4: Source Q | H4: Primary type | I4: Flags | J4: Source answer-key PDF | K4: Source key
A5: 1 | B5: D | C5: Las respuestas a) y b) son correctas. | D5: Illes Balears | E5: 2022 | F5: illes-balears/2022 | G5: 1 | H5: Named clinical-case section | J5: AD_ILLES_BALEARS_2022__ANSWER_KEY__answer-key__plantilla-correctora-del-examen.pdf | K5: illes-balears|2022|caso-1|1
A6: 2 | B6: C | C6: La obesidad no ha mostrado ser un factor de riesgo para el desarrollo del cáncer de colon. | D6: Illes Balears | E6: 2022 | F6: illes-balears/2022 | G6: 2 | H6: Named clinical-case section | I6: negated | J6: AD_ILLES_BALEARS_2022__ANSWER_KEY__answer-key__plantilla-correctora-del-examen.pdf | K6: illes-balears|2022|caso-1|2
A7: 3 | B7: A | C7: El cáncer de colon incrementa claramente su incidencia a partir de los 50. | D7: Illes Balears | E7: 2022 | F7: illes-balears/2022 | G7: 3 | H7: Named clinical-case section | J7: AD_ILLES_BALEARS_2022__ANSWER_KEY__answer-key__plantilla-correctora-del-examen.pdf | K7: illes-balears|2022|caso-1|3
A8: 4 | B8: B | C8: La dieta rica en frutas y vegetales disminuye el riesgo de CCR. | D8: Illes Balears | E8: 2022 | F8: illes-balears/2022 | G8: 4 | H8: Named clinical-case section | J8: AD_ILLES_BALEARS_2022__ANSWER_KEY__answer-key__plantilla-correctora-del-examen.pdf | K8: illes-balears|2022|caso-1|4
A9: 5 | B9: B | C9: Cumple criterios para ser incluido en el programa de cribado del CCR. | D9: Illes Balears | E9: 2022 | F9: illes-balears/2022 | G9: 5 | H9: Named clinical-case section | J9: AD_ILLES_BALEARS_2022__ANSWER_KEY__answer-key__plantilla-correctora-del-examen.pdf | K9: illes-balears|2022|caso-1|5
A10: 6 | B10: C | C10: Se debe ofrecer al paciente hacer una colonoscopia. | D10: Illes Balears | E10: 2022 | F10: illes-balears/2022 | G10: 6 | H10: Named clinical-case section | J10: AD_ILLES_BALEARS_2022__ANSWER_KEY__answer-key__plantilla-correctora-del-examen.pdf | K10: illes-balears|2022|caso-1|6
A11: 7 | B11: D | C11: Las endoscopias del programa de cribado pueden hacerse en cualquier gabinete y por cualquier tipo de endoscopista independientemente de su tasa de detección de adenomas. | D11: Illes Balears | E11: 2022 | F11: illes-balears/2022 | G11: 7 | H11: Named clinical-case section | I11: negated | J11: AD_ILLES_BALEARS_2022__ANSWER_KEY__answer-key__plantilla-correctora-del-examen.pdf | K11: illes-balears|2022|caso-1|7
A12: 8 | B12: A | C12: Se debe repetir la colonoscopia para conseguir una puntuación total de 6 puntos (o superior) con un mínimo de dos puntos en cada tramo. | D12: Illes Balears | E12: 2022 | F12: illes-balears/2022 | G12: 8 | H12: Named clinical-case section | J12: AD_ILLES_BALEARS_2022__ANSWER_KEY__answer-key__plantilla-correctora-del-examen.pdf | K12: illes-balears|2022|caso-1|8
A13: 9 | B13: B | C13: La lesión ha quedado curada tras la resección endoscópica. | D13: Illes Balears | E13: 2022 | F13: illes-balears/2022 | G13: 9 | H13: Named clinical-case section | J13: AD_ILLES_BALEARS_2022__ANSWER_KEY__answer-key__plantilla-correctora-del-examen.pdf | K13: illes-balears|2022|caso-1|9
A14: 10 | B14: D | C14: Una revisión endoscópica dentro de tres años es suficiente. | D14: Illes Balears | E14: 2022 | F14: illes-balears/2022 | G14: 10 | H14: Named clinical-case section | J14: AD_ILLES_BALEARS_2022__ANSWER_KEY__answer-key__plantilla-correctora-del-examen.pdf | K14: illes-balears|2022|caso-1|10
A15: 11 | B15: C | C15: En este caso se recomienda el control por medio de una SOH bianual. | D15: Illes Balears | E15: 2022 | F15: illes-balears/2022 | G15: 11 | H15: Named clinical-case section | J15: AD_ILLES_BALEARS_2022__ANSWER_KEY__answer-key__plantilla-correctora-del-examen.pdf | K15: illes-balears|2022|caso-1|11
A16: 12 | B16: B | C16: Requiere colonoscopia por la clínica que presenta para descartar un CCR. | D16: Illes Balears | E16: 2022 | F16: illes-balears/2022 | G16: 12 | H16: Named clinical-case section | J16: AD_ILLES_BALEARS_2022__ANSWER_KEY__answer-key__plantilla-correctora-del-examen.pdf | K16: illes-balears|2022|caso-1|12
A17: 13 | B17: C | C17: Estadio T1N0M0. | D17: Illes Balears | E17: 2022 | F17: illes-balears/2022 | G17: 14 | H17: Named clinical-case section | J17: AD_ILLES_BALEARS_2022__ANSWER_KEY__answer-key__plantilla-correctora-del-examen.pdf | K17: illes-balears|2022|caso-1|14
A18: 14 | B18: C | C18: Es susceptible de una resección en bloque mediante una disección endoscópica submucosa. | D18: Illes Balears | E18: 2022 | F18: illes-balears/2022 | G18: 15 | H18: Named clinical-case section | J18: AD_ILLES_BALEARS_2022__ANSWER_KEY__answer-key__plantilla-correctora-del-examen.pdf | K18: illes-balears|2022|caso-1|15
A19: 15 | B19: A | C19: La resección endoscópica ha sido curativa. | D19: Illes Balears | E19: 2022 | F19: illes-balears/2022 | G19: 16 | H19: Named clinical-case section | J19: AD_ILLES_BALEARS_2022__ANSWER_KEY__answer-key__plantilla-correctora-del-examen.pdf | K19: illes-balears|2022|caso-1|16
A20: 16 | B20: C | C20: Requiere un control endoscópico de forma precoz, que es aceptable a los seis meses. | D20: Illes Balears | E20: 2022 | F20: illes-balears/2022 | G20: 17 | H20: Named clinical-case section | J20: AD_ILLES_BALEARS_2022__ANSWER_KEY__answer-key__plantilla-correctora-del-examen.pdf | K20: illes-balears|2022|caso-1|17
A21: 17 | B21: A | C21: Si es factible, la resección endoscópica de las lesiones ha de ser el tratamiento de elección. | D21: Illes Balears | E21: 2022 | F21: illes-balears/2022 | G21: 18 | H21: Named clinical-case section | J21: AD_ILLES_BALEARS_2022__ANSWER_KEY__answer-key__plantilla-correctora-del-examen.pdf | K21: illes-balears|2022|caso-1|18
A22: 18 | B22: B | C22: Puede ser susceptible de un estudio genético complementario. | D22: Illes Balears | E22: 2022 | F22: illes-balears/2022 | G22: 19 | H22: Named clinical-case section | J22: AD_ILLES_BALEARS_2022__ANSWER_KEY__answer-key__plantilla-correctora-del-examen.pdf | K22: illes-balears|2022|caso-1|19
A23: 19 | B23: A | C23: Poliposis adenomatosa familiar clásica. | D23: Illes Balears | E23: 2022 | F23: illes-balears/2022 | G23: 20 | H23: Named clinical-case section | J23: AD_ILLES_BALEARS_2022__ANSWER_KEY__answer-key__plantilla-correctora-del-examen.pdf | K23: illes-balears|2022|caso-1|20
... A27: 23 | B27: D | C27: Todas las respuestas anteriores son falsas. | D27: Illes Balears | E27: 2022 | F27: illes-balears/2022 | G27: 24 | H27: Named clinical-case section | J27: AD_ILLES_BALEARS_2022__ANSWER_KEY__answer-key__plantilla-correctora-del-examen.pdf | K27: illes-balears|2022|caso-1|24
A28: 24 | B28: B | C28: La endoscopia digestiva está indicada como método diagnóstico inicial en todos los pacientes que muestran síntomas típicos de ERGE. | D28: Illes Balears | E28: 2022 | F28: illes-balears/2022 | G28: 25 | H28: Named clinical-case section | I28: negated | J28: AD_ILLES_BALEARS_2022__ANSWER_KEY__answer-key__plantilla-correctora-supuesto-2.pdf | K28: illes-balears|2022|caso-2|25
A29: 25 | B29: D | C29: En los pacientes con gastroscopia normal y con pirosis que no responden al tratamiento médico con inhibidores de la bomba de protones, se debe descartar una enfermedad por reflujo gastroesofágico y no se deben hacer otros estudios. | D29: Illes Balears | E29: 2022 | F29: illes-balears/2022 | G29: 26 | H29: Named clinical-case section | I29: negated | J29: AD_ILLES_BALEARS_2022__ANSWER_KEY__answer-key__plantilla-correctora-supuesto-2.pdf | K29: illes-balears|2022|caso-2|26
A30: 26 | B30: C | C30: Las alteraciones de la motilidad del cuerpo esofágico no influyen en el reflujo gastroesofágico. | D30: Illes Balears | E30: 2022 | F30: illes-balears/2022 | G30: 27 | H30: Named clinical-case section | I30: negated | J30: AD_ILLES_BALEARS_2022__ANSWER_KEY__answer-key__plantilla-correctora-supuesto-2.pdf | K30: illes-balears|2022|caso-2|27
A31: 27 | B31: B | C31: No hay diferencias en la gravedad de la pirosis entre los diferentes fenotipos de reflujo gastroesofágico. | D31: Illes Balears | E31: 2022 | F31: illes-balears/2022 | G31: 28 | H31: Named clinical-case section | J31: AD_ILLES_BALEARS_2022__ANSWER_KEY__answer-key__plantilla-correctora-supuesto-2.pdf | K31: illes-balears|2022|caso-2|28
A32: 28 | B32: B | C32: Existe una buena correlación entre la intensidad o la frecuencia de los síntomas de ERGE y la gravedad de las lesiones endoscópicas. | D32: Illes Balears | E32: 2022 | F32: illes-balears/2022 | G32: 29 | H32: Named clinical-case section | I32: negated | J32: AD_ILLES_BALEARS_2022__ANSWER_KEY__answer-key__plantilla-correctora-supuesto-2.pdf | K32: illes-balears|2022|caso-2|29
A33: 29 | B33: C | C33: Supone una o más lesiones de la mucosa, con confluencia y afectación menor del 75 % de la circunferencia del esófago. | D33: Illes Balears | E33: 2022 | F33: illes-balears/2022 | G33: 30 | H33: Named clinical-case section | J33: AD_ILLES_BALEARS_2022__ANSWER_KEY__answer-key__plantilla-correctora-supuesto-2.pdf | K33: illes-balears|2022|caso-2|30
A34: 30 | B34: C | C34: Impedancia intraluminal multicanal asociada a pH-metría. | D34: Illes Balears | E34: 2022 | F34: illes-balears/2022 | G34: 31 | H34: Named clinical-case section | J34: AD_ILLES_BALEARS_2022__ANSWER_KEY__answer-key__plantilla-correctora-supuesto-2.pdf | K34: illes-balears|2022|caso-2|31
A35: 31 | B35: C | C35: No interfiere su interpretación si hay alteraciones de la motilidad o histológicas del esófago. | D35: Illes Balears | E35: 2022 | F35: illes-balears/2022 | G35: 32 | H35: Named clinical-case section | I35: negated | J35: AD_ILLES_BALEARS_2022__ANSWER_KEY__answer-key__plantilla-correctora-supuesto-2.pdf | K35: illes-balears|2022|caso-2|32
A36: 32 | B36: D | C36: Edad superior a 50 años sin diferencia de sexo y raza. | D36: Illes Balears | E36: 2022 | F36: illes-balears/2022 | G36: 33 | H36: Named clinical-case section | I36: negated | J36: AD_ILLES_BALEARS_2022__ANSWER_KEY__answer-key__plantilla-correctora-supuesto-2.pdf | K36: illes-balears|2022|caso-2|33
A37: 33 | B37: C | C37: Siempre se aconseja biopsiar un esófago de Barrett en presencia de esofagitis por reflujo. | D37: Illes Balears | E37: 2022 | F37: illes-balears/2022 | G37: 34 | H37: Named clinical-case section | I37: negated | J37: AD_ILLES_BALEARS_2022__ANSWER_KEY__answer-key__plantilla-correctora-supuesto-2.pdf | K37: illes-balears|2022|caso-2|34
A38: 34 | B38: D | C38: Todas las respuestas anteriores son correctas. | D38: Illes Balears | E38: 2022 | F38: illes-balears/2022 | G38: 35 | H38: Named clinical-case section | J38: AD_ILLES_BALEARS_2022__ANSWER_KEY__answer-key__plantilla-correctora-supuesto-2.pdf | K38: illes-balears|2022|caso-2|35
A39: 35 | B39: B | C39: La longitud del esófago. | D39: Illes Balears | E39: 2022 | F39: illes-balears/2022 | G39: 36 | H39: Named clinical-case section | I39: negated | J39: AD_ILLES_BALEARS_2022__ANSWER_KEY__answer-key__plantilla-correctora-supuesto-2.pdf | K39: illes-balears|2022|caso-2|36
A40: 36 | B40: B | C40: Se deben hacer biopsias en botes separados de los cuatro cuadrantes cada 2 cm de esófago de Barrett o cada 1 cm si hay displasia severa previa. | D40: Illes Balears | E40: 2022 | F40: illes-balears/2022 | G40: 37 | H40: Named clinical-case section | J40: AD_ILLES_BALEARS_2022__ANSWER_KEY__answer-key__plantilla-correctora-supuesto-2.pdf | K40: illes-balears|2022|caso-2|37
A41: 37 | B41: C | C41: Ante el hallazgo de displasia indefinida se recomienda una revisión endoscópica en dos años. | D41: Illes Balears | E41: 2022 | F41: illes-balears/2022 | G41: 38 | H41: Named clinical-case section | I41: negated | J41: AD_ILLES_BALEARS_2022__ANSWER_KEY__answer-key__plantilla-correctora-supuesto-2.pdf | K41: illes-balears|2022|caso-2|38
A42: 38 | B42: B | C42: La cirugía antirreflujo se considera una opción más eficaz que el tratamiento médico con IBP para los pacientes con esófago de Barrett. | D42: Illes Balears | E42: 2022 | F42: illes-balears/2022 | G42: 39 | H42: Named clinical-case section | I42: negated | J42: AD_ILLES_BALEARS_2022__ANSWER_KEY__answer-key__plantilla-correctora-supuesto-2.pdf | K42: illes-balears|2022|caso-2|39
A43: 39 | B43: B | C43: La ablación por radiofrecuencia es coste-efectiva en todos los casos de esófago de Barrett de longitud larga (superior a 5 cm). | D43: Illes Balears | E43: 2022 | F43: illes-balears/2022 | G43: 40 | H43: Named clinical-case section | I43: negated | J43: AD_ILLES_BALEARS_2022__ANSWER_KEY__answer-key__plantilla-correctora-supuesto-2.pdf | K43: illes-balears|2022|caso-2|40
A44: 40 | B44: A | C44: Planificar una resección endoscópica de la lesión con displasia de grado alto y posteriormente una ablación con radiofrecuencia de todo el esófago de Barrett. | D44: Illes Balears | E44: 2022 | F44: illes-balears/2022 | G44: 41 | H44: Named clinical-case section | J44: AD_ILLES_BALEARS_2022__ANSWER_KEY__answer-key__plantilla-correctora-supuesto-2.pdf | K44: illes-balears|2022|caso-2|41
...

Sheet Case Contexts
A1: Selected Shared Clinical Contexts
A2: Electronic trace table; complete print-readable contexts are inline in Questionnaire. Long source text is split here into visible continuation rows.
A4: Context ID | B4: Kind / part | C4: Clinical context | D4: Questionnaire items | E4: Source pair | F4: Source question numbers | G4: PDF pages | H4: Source exam PDF | I4: Source PDF SHA256
A5: illes-balears-2022-base-caso-1 | B5: Base case narrative · 1/1 | C5: Paciente de 57 años, sin antecedentes personales ni familiares de cáncer de colon ni de cáncer en otras localizaciones, fumador de 22 cigarrillos al día, con hábitos de vida sedentarios, enolismo de 60 gr/día, obesidad con un índice de masa corporal de 37 y una dieta rica en carnes rojas y procesadas. | D5: 1, 2, 3, 4, 5, 6, 7, 8, 9, 10, 11, 12, 13, 14, 15, 16, 17, 18, 19, 20, 21, 22, 23 | E5: illes-balears/2022 | F5: 1-24 | G5: 3 | H5: exams-other-regions-spain-pdfs/illes-balears/2022/exam/exam__cuadernillo-de-examen-aparato-digestivo-fea.pdf | I5: c90fbb40ff4e10d7c01d175f5d2da8cb90bc002c4c856e378ad6a75908faf626
A6: illes-balears-2022-base-caso-2 | B6: Base case narrative · 1/3 | C6: Varón de 63 años remitido a la unidad de endoscopia para hacerle una gastroscopia por un reflujo de larga evolución (superior a 10 años). El paciente es obeso, hipertenso y fumador. Refiere disfagia a sólidos desde hace un mes. Se hace una gastroscopia que detecta a 32 cm de las arcadas dentarias la presencia de una mucosa ectópica que se extiende hasta la unión esofagogástrica situada a 38 cm de las arcadas dentarias en donde se aprecian signos de esofagitis por reflujo grado C. | D6: 24, 25, 26, 27, 28, 29, 30, 31, 32, 33, 34, 35, 36, 37, 38, 39, 40, 41, 42, 43, 44, 45, 46 | E6: illes-balears/2022 | F6: 25-48 | G6: 11 | H6: exams-other-regions-spain-pdfs/illes-balears/2022/exam/exam__cuadernillo-de-examen-aparato-digestivo-fea.pdf | I6: c90fbb40ff4e10d7c01d175f5d2da8cb90bc002c4c856e378ad6a75908faf626
A7: illes-balears-2022-base-caso-2 | B7: Base case narrative · 2/3 | C7: Se pauta un tratamiento médico y se hace una nueva gastroscopia a las ocho semanas. En ella se aprecia la mucosa ectópica descrita previamente sugestiva de esófago de Barrett (C5M6) con una cicatrización completa de la esofagitis por reflujo y a 35 cm de las arcadas dentarias se aprecia un área irregular sobreelevada de unos 8 mm (0-Is) diferente al resto de la mucosa circundante. Se hacen biopsias de forma aleatoria de la lesión descrita, suponiendo que puede tratarse de un esófago de Barrett según el protocolo de Seattle. Los resultados de la lesión visible en el esófago confirman un esófago | D7: 24, 25, 26, 27, 28, 29, 30, 31, 32, 33, 34, 35, 36, 37, 38, 39, 40, 41, 42, 43, 44, 45, 46 | E7: illes-balears/2022 | F7: 25-48 | G7: 11 | H7: exams-other-regions-spain-pdfs/illes-balears/2022/exam/exam__cuadernillo-de-examen-aparato-digestivo-fea.pdf | I7: c90fbb40ff4e10d7c01d175f5d2da8cb90bc002c4c856e378ad6a75908faf626
A8: illes-balears-2022-base-caso-2 | B8: Base case narrative · 3/3 | C8: de Barrett con metaplasia intestinal y presencia de focos de displasia de grado alto y las biopsias aleatorias confirmaban el esófago de Barrett sin displasia. Se planifica una estrategia de tratamiento y seguimiento. | D8: 24, 25, 26, 27, 28, 29, 30, 31, 32, 33, 34, 35, 36, 37, 38, 39, 40, 41, 42, 43, 44, 45, 46 | E8: illes-balears/2022 | F8: 25-48 | G8: 11 | H8: exams-other-regions-spain-pdfs/illes-balears/2022/exam/exam__cuadernillo-de-examen-aparato-digestivo-fea.pdf | I8: c90fbb40ff4e10d7c01d175f5d2da8cb90bc002c4c856e378ad6a75908faf626
A9: illes-balears-2022-base-caso-3 | B9: Base case narrative · 1/3 | C9: Paciente varón de 62 años con antecedentes de enolismo superior a 60 g/día de veinte años de evolución y fumador de 25 paquetes/año desde los 17 años. Antecedente de dos ingresos por pancreatitis agudas leves en los últimos tres años. En los últimos tres meses presenta un cuadro de diarrea en forma de cuatro deposiciones al día, dolor abdominal continuo y diario, localizado en el epigastrio que no mejora con paracetamol. Además, refiere que ha perdido cuatro quilos. Se le hace una gastroscopia que es normal. Una TC abdominal revela la presencia de múltiples calcificaciones parenquimatosas en | D9: 47, 48, 49, 50, 51, 52, 53, 54, 55, 56, 57, 58, 59, 60, 61, 62, 63, 64, 65, 66, 67, 68, 69, 70 | E9: illes-balears/2022 | F9: 49-72 | G9: 19 | H9: exams-other-regions-spain-pdfs/illes-balears/2022/exam/exam__cuadernillo-de-examen-aparato-digestivo-fea.pdf | I9: c90fbb40ff4e10d7c01d175f5d2da8cb90bc002c4c856e378ad6a75908faf626
A10: illes-balears-2022-base-caso-3 | B10: Base case narrative · 2/3 | C10: la cabeza del páncreas, dilatación del conducto pancreático principal, una lesión quística de 10 mm en el cuerpo pancreático y atrofia de la cola de páncreas. Los coprocultivos, los parásitos en heces y la toxina de Clostridium difficile en heces son negativos, la serología de celiaquía negativa y las hormonas tiroideas son normales. Elementos relevantes de la analítica. Glucosa: 124 mg/dl, GGT: 101 U/L, AST: 55 U/L, ALT: 65 U/L, VCM: 102 fl, BI total: 1,4 mg/dl, triglicéridos: 180 mg/dl, amilasa: 125 U/L, lipasa: 25 U/L. | D10: 47, 48, 49, 50, 51, 52, 53, 54, 55, 56, 57, 58, 59, 60, 61, 62, 63, 64, 65, 66, 67, 68, 69, 70 | E10: illes-balears/2022 | F10: 49-72 | G10: 19 | H10: exams-other-regions-spain-pdfs/illes-balears/2022/exam/exam__cuadernillo-de-examen-aparato-digestivo-fea.pdf | I10: c90fbb40ff4e10d7c01d175f5d2da8cb90bc002c4c856e378ad6a75908faf626
A11: illes-balears-2022-base-caso-3 | B11: Base case narrative · 3/3 | C11: El resto del hemograma y de la bioquímica está dentro de valores normales. | D11: 47, 48, 49, 50, 51, 52, 53, 54, 55, 56, 57, 58, 59, 60, 61, 62, 63, 64, 65, 66, 67, 68, 69, 70 | E11: illes-balears/2022 | F11: 49-72 | G11: 19 | H11: exams-other-regions-spain-pdfs/illes-balears/2022/exam/exam__cuadernillo-de-examen-aparato-digestivo-fea.pdf | I11: c90fbb40ff4e10d7c01d175f5d2da8cb90bc002c4c856e378ad6a75908faf626
A12: illes-balears-2022-caso-3-transition-01 | B12: Shared clinical context · 1/1 | C12: Las pruebas para determinar la insuficiencia pancreática exocrina demuestran una insuficiencia pancreática exocrina (IPE) grave. | D12: 53, 54, 55, 56, 57, 58, 59, 60, 61, 62, 63, 64, 65, 66, 67, 68, 69, 70 | E12: illes-balears/2022 | F12: 55,56,57,58,59,60,61 | G12: 21 | H12: exams-other-regions-spain-pdfs/illes-balears/2022/exam/exam__cuadernillo-de-examen-aparato-digestivo-fea.pdf | I12: c90fbb40ff4e10d7c01d175f5d2da8cb90bc002c4c856e378ad6a75908faf626
